Workbook

Sheet Attendance
A1: Click here for guidelines to fill out this sheet along with videos | F1: This section will be filled by QAE on the batch start date
D2: Trainer Name | F2: M Vikram | AB2: Start Date | AD2: 46171
AH3: Click Here to Upload the Photograph | AL3: Click Here to Upload the Photograph | AP3: Click Here to Upload the Photograph | AT3: Click Here to Upload the Photograph | AX3: Click Here to Upload the Photograph | BB3: Click Here to Upload the Photograph | BF3: Click Here to Upload the Photograph | BJ3: Click Here to Upload the Photograph | BN3: Click Here to Upload the Photograph | BR3: Click Here to Upload the Photograph | BW3: Click Here to Upload the Photograph | CA3: Click Here to Upload the Photograph | CE3: Click Here to Upload the Photograph | CI3: Click Here to Upload the Photograph | CM3: Click Here to Upload the Photograph | CQ3: Click Here to Upload the Photograph | CU3: Click Here to Upload the Photograph | CY3: Click Here to Upload the Photograph | DC3: Click Here to Upload the Photograph | DG3: Click Here to Upload the Photograph | DK3: Click Here to Upload the Photograph | DO3: Click Here to Upload the Photograph | DS3: Click Here to Upload the Photograph | DW3: Click Here to Upload the Photograph | EA3: Click Here to Upload the Photograph | EE3: Click Here to Upload the Photograph | EI3: Click Here to Upload the Photograph | EM3: Click Here to Upload the Photograph | EQ3: Click Here to Upload the Photograph | EU3: Click Here to Upload the Photograph | EZ3: Click Here to Upload the Photograph | FD3: Click Here to Upload the Photograph | FH3: Click Here to Upload the Photograph | FL3: Click Here to Upload the Photograph | FP3: Click Here to Upload the Photograph | FT3: Click Here to Upload the Photograph | FX3: Click Here to Upload the Photograph | GB3: Click Here to Upload the Photograph | GF3: Click Here to Upload the Photograph | GJ3: Click Here to Upload the Photograph | GN3: Click Here to Upload the Photograph | GR3: Click Here to Upload the Photograph | GV3: Click Here to Upload the Photograph | GZ3: Click Here to Upload the Photograph | HD3: Click Here to Upload the Photograph | HH3: Click Here to Upload the Photograph | HL3: Click Here to Upload the Photograph | HP3: Click Here to Upload the Photograph | HT3: Click Here to Upload the Photograph | HX3: Click Here to Upload the Photograph | IB3: Click Here to Upload the Photograph | IF3: Click Here to Upload the Photograph | IJ3: Click Here to Upload the Photograph | IN3: Click Here to Upload the Photograph | IR3: Click Here to Upload the Photograph | IV3: Click Here to Upload the Photograph | IZ3: Click Here to Upload the Photograph | JD3: Click Here to Upload the Photograph | JH3: Click Here to Upload the Photograph | JL3: Click Here to Upload the Photograph | JP3: Click Here to Upload the Photograph | JT3: Click Here to Upload the Photograph | JX3: Click Here to Upload the Photograph | KB3: Click Here to Upload the Photograph | KF3: Click Here to Upload the Photograph | KJ3: Click Here to Upload the Photograph | KN3: Click Here to Upload the Photograph | KR3: Click Here to Upload the Photograph | KV3: Click Here to Upload the Photograph | KZ3: Click Here to Upload the Photograph | LD3: Click Here to Upload the Photograph | LH3: Click Here to Upload the Photograph | LL3: Click Here to Upload the Photograph | LP3: Click Here to Upload the Photograph | LT3: Click Here to Upload the Photograph | LX3: Click Here to Upload the Photograph | MB3: Click Here to Upload the Photograph | MF3: Click Here to Upload the Photograph | MJ3: Click Here to Upload the Photograph | MN3: Click Here to Upload the Photograph | MR3: Click Here to Upload the Photograph | MV3: Click Here to Upload the Photograph | MZ3: Click Here to Upload the Photograph | ND3: Click Here to Upload the Photograph | NH3: Click Here to Upload the Photograph | NL3: Click Here to Upload the Photograph | NP3: Click Here to Upload the Photograph | NT3: Click Here to Upload the Photograph | NX3: Click Here to Upload the Photograph
D4: Language | AB4: End Date | AD4: =AD2+89 -> 46260 | AH4: Note: Please update the dates in the below rows only for the days when sessions are delivered (consider only working/training days). Do not enter dates for holidays or non-training days. Also, kindly avoid leaving any cells blank with dates, as it may cause errors in aspirant attendance percentage. | BV4: Aspirant Skillfy App Downloaded or Not | EY4: Number of Courses Completed in Skillfy App
D5: Aspirants Base Centres | F5: CFRSI - Chennai-Batch-1 | AD5: Fill date (DD-MM-YY) | AH5: =AD2 -> 46171 | AL5: =AH5+1 -> 46172 | AP5: 46174 | AT5: =AP5+1 -> 46175 | AX5: =AT5+1 -> 46176 | BB5: =AX5+1 -> 46177 | BF5: =BB5+1 -> 46178 | BJ5: 46181 | BN5: =BJ5+1 -> 46182 | BR5: =BN5+1 -> 46183 | BW5: 46184 | CA5: 46185 | CE5: 46186 | CI5: 46188 | CM5: 46189 | CQ5: 46190 | CU5: 46191 | CY5: 46192 | DC5: 46195 | DG5: 46196 | DK5: 46197 | DO5: 46198 | DS5: 46199 | DW5: 46200 | EA5: 46202 | EE5: 46203 | EI5: 46204 | EM5: 46205 | EQ5: 46206 | EU5: 46209 | EY5: 46210 | FC5: 46211 | FH5: 46212 | FL5: 46213 | FP5: 46214 | FT5: 46216 | FX5: 46217 | GB5: 46218 | GF5: 46219 | GJ5: 46220 | GN5: 46223 | GR5: 46224 | GV5: 46225 | GZ5: 46226 | HD5: 46227 | HH5: 46228 | HL5: 46230
F6: All these cells will be generated automatically
A7: Sr No. | B7: Asp ID | C7: Email | D7: Name | E7: SS | F7: CS | G7: ML | H7: CE | I7: AP | J7: Ad.Exl | K7: CES | L7: PT | M7: IS | N7: DS | O7: SB | P7: MTP | Q7: PS | R7: NY | S7: PY | T7: SQL | U7: GO | V7: Ab | W7: SP | X7: EP | Y7: TP | Z7: QAE | AA7: Skillfy App Downloaded or Not | AB7: Courses Completed in Skillfy App | AC7: Total Sessions | AD7: Sessions Attended | AE7: No of Days Attended | AF7: Day Wise Attendance % | AG7: Session Wise Arrendance % | AH7: S-1 | AI7: S-2 | AJ7: S-3 | AK7: S-4 | AL7: S-1 | AM7: S-2 | AN7: S-3 | AO7: S-4 | AP7: S-1 | AQ7: S-2 | AR7: S-3 | AS7: S-4 | AT7: S-1 | AU7: S-2 | AV7: S-3 | AW7: S-4 | AX7: S-1 | AY7: S-2 | AZ7: S-3 | BA7: S-4 | BB7: S-1 | BC7: S-2 | BD7: S-3 | BE7: S-4 | BF7: S-1 | BG7: S-2 | BH7: S-3 | BI7: S-4 | BJ7: S-1 | BK7: S-2 | BL7: S-3 | BM7: S-4 | BN7: S-1 | BO7: S-2 | BP7: S-3 | BQ7: S-4 | BR7: S-1 | BS7: S-2 | BT7: S-3 | BU7: S-4 | BW7: S-1 | BX7: S-2 | BY7: S-3 | BZ7: S-4 | CA7: S-1 | CB7: S-2 | CC7: S-3 | CD7: S-4 | CE7: S-1 | CF7: S-2 | CG7: S-3 | CH7: S-4 | CI7: S-1 | CJ7: S-2 | CK7: S-3 | CL7: S-4 | CM7: S-1 | CN7: S-2 | CO7: S-3 | CP7: S-4 | CQ7: S-1 | CR7: S-2 | CS7: S-3 | CT7: S-4 | CU7: S-1 | CV7: S-2 | CW7: S-3 | CX7: S-4 | CY7: S-1 | CZ7: S-2 | DA7: S-3 | DB7: S-4 | DC7: S-1 | DD7: S-1 | DE7: S-3 | DF7: S-4 | DG7: S-1 | DH7: S-2 | DI7: S-3 | DJ7: S-4 | DK7: S-1 | DL7: S-2 | DM7: S-3 | DN7: S-4 | DO7: S-1 | DP7: S-2 | DQ7: S-3 | DR7: S-4 | DS7: S-1 | DT7: S-2 | DU7: S-3 | DV7: S-4 | DW7: S-1 | DX7: S-2 | DY7: S-3 | DZ7: S-4 | EA7: S-1 | EB7: S-2 | EC7: S-3 | ED7: S-4 | EE7: S-1 | EF7: S-2 | EG7: S-3 | EH7: S-4 | EI7: S-1 | EJ7: S-2 | EK7: S-3 | EL7: S-4 | EM7: S-1 | EN7: S-2 | EO7: S-3 | EP7: S-4 | EQ7: S-1 | ER7: S-2 | ES7: S-3 | ET7: S-4 | EU7: S-1 | EV7: S-2 | EW7: S-3 | EX7: S-4 | EZ7: S-1 | FA7: S-2 | FB7: S-3 | FC7: S-4 | FD7: S-1 | FE7: S-2 | FF7: S-3 | FG7: S-4 | FH7: S-1 | FI7: S-2 | FJ7: S-3 | FK7: S-4 | FL7: S-1 | FM7: S-2 | FN7: S-3 | FO7: S-4 | FP7: S-1 | FQ7: S-2 | FR7: S-3 | FS7: S-4 | FT7: S-1 | FU7: S-2 | FV7: S-3 | FW7: S-4 | FX7: S-1 | FY7: S-2 | FZ7: S-3 | GA7: S-4 | GB7: S-1 | GC7: S-2 | GD7: S-3 | GE7: S-4 | GF7: S-1 | GG7: S-2 | GH7: S-3 | GI7: S-4 | GJ7: S-1 | GK7: S-2 | GL7: S-3 | GM7: S-4 | GN7: S-1 | GO7: S-2 | GP7: S-3 | GQ7: S-4 | GR7: S-1 | GS7: S-2 | GT7: S-3 | GU7: S-4 | GV7: S-1 | GW7: S-2 | GX7: S-3 | GY7: S-4 | GZ7: S-1 | HA7: S-2 | HB7: S-3 | HC7: S-4 | HD7: S-1 | HE7: S-2 | HF7: S-3 | HG7: S-4 | HH7: S-1 | HI7: S-2 | HJ7: S-3 | HK7: S-4 | HL7: S-1 | HM7: S-2 | HN7: S-3 | HO7: S-4 | HP7: S-1 | HQ7: S-2 | HR7: S-3 | HS7: S-4 | HT7: S-1 | HU7: S-2 | HV7: S-3 | HW7: S-4 | HX7: S-1 | HY7: S-2 | HZ7: S-3 | IA7: S-4 | IB7: S-1 | IC7: S-2 | ID7: S-3 | IE7: S-4 | IF7: S-1 | IG7: S-2 | IH7: S-3 | II7: S-4 | IJ7: S-1 | IK7: S-2 | IL7: S-3 | IM7: S-4 | IN7: S-1 | IO7: S-2 | IP7: S-3 | IQ7: S-4 | IR7: S-1 | IS7: S-2 | IT7: S-3 | IU7: S-4 | IV7: S-1 | IW7: S-2 | IX7: S-3 | IY7: S-4 | IZ7: S-1 | JA7: S-2 | JB7: S-3 | JC7: S-4 | JD7: S-1 | JE7: S-2 | JF7: S-3 | JG7: S-4 | JH7: S-1 | JI7: S-2 | JJ7: S-3 | JK7: S-4 | JL7: S-1 | JM7: S-2 | JN7: S-3 | JO7: S-4 | JP7: S-1 | JQ7: S-2 | JR7: S-3 | JS7: S-4 | JT7: S-1 | JU7: S-2 | JV7: S-3 | JW7: S-4 | JX7: S-1 | JY7: S-2 | JZ7: S-3 | KA7: S-4 | KB7: S-1 | KC7: S-2 | KD7: S-3 | KE7: S-4 | KF7: S-1 | KG7: S-2 | KH7: S-3 | KI7: S-4 | KJ7: S-1 | KK7: S-2 | KL7: S-3 | KM7: S-4 | KN7: S-1 | KO7: S-2 | KP7: S-3 | KQ7: S-4 | KR7: S-1 | KS7: S-2 | KT7: S-3 | KU7: S-4 | KV7: S-1 | KW7: S-2 | KX7: S-3 | KY7: S-4 | KZ7: S-1 | LA7: S-2 | LB7: S-3 | LC7: S-4 | LD7: S-1 | LE7: S-2 | LF7: S-3 | LG7: S-4 | LH7: S-1 | LI7: S-2 | LJ7: S-3 | LK7: S-4 | LL7: S-1 | LM7: S-2 | LN7: S-3 | LO7: S-4 | LP7: S-1 | LQ7: S-2 | LR7: S-3 | LS7: S-4 | LT7: S-1 | LU7: S-2 | LV7: S-3 | LW7: S-4 | LX7: S-1 | LY7: S-2 | LZ7: S-3 | MA7: S-4 | MB7: S-1 | MC7: S-2 | MD7: S-3 | ME7: S-4 | MF7: S-1 | MG7: S-2 | MH7: S-3 | MI7: S-4 | MJ7: S-1 | MK7: S-2 | ML7: S-3 | MM7: S-4 | MN7: S-1 | MO7: S-2 | MP7: S-3 | MQ7: S-4 | MR7: S-1 | MS7: S-2 | MT7: S-3 | MU7: S-4 | MV7: S-1 | MW7: S-2 | MX7: S-3 | MY7: S-4 | MZ7: S-1 | NA7: S-2 | NB7: S-3 | NC7: S-4 | ND7: S-1 | NE7: S-2 | NF7: S-3 | NG7: S-4 | NH7: S-1 | NI7: S-2 | NJ7: S-3 | NK7: S-4 | NL7: S-1 | NM7: S-2 | NN7: S-3 | NO7: S-4 | NP7: S-1 | NQ7: S-2 | NR7: S-3 | NS7: S-4 | NT7: S-1 | NU7: S-2 | NV7: S-3 | NW7: S-4 | NX7: S-1 | NY7: S-2 | NZ7: S-3 | OA7: S-4 | OB7: S-1 | OC7: S-2 | OD7: S-3 | OE7: S-4 | OF7: S-1 | OG7: S-2 | OH7: S-3 | OI7: S-4 | OJ7: S-1 | OK7: S-2 | OL7: S-3 | OM7: S-4 | ON7: S-1 | OO7: S-2 | OP7: S-3 | OQ7: S-4 | OR7: S-1 | OS7: S-2 | OT7: S-3 | OU7: S-4 | OV7: S-1 | OW7: S-2 | OX7: S-3 | OY7: S-4 | OZ7: S-1 | PA7: S-2 | PB7: S-3 | PC7: S-4 | PD7: S-1 | PE7: S-2 | PF7: S-3 | PG7: S-4
A8: 1 | B8: 351008 | C8: kishorekumarr307@gmail.com | D8: Kishorekumar R | E8: =IF(COUNTIF($AH8:$UG8,E$7)=0,"",COUNTIF($AH8:$UG8,E$7)) | F8: =IF(COUNTIF($AH8:$UG8,F$7)=0,"",COUNTIF($AH8:$UG8,F$7)) | G8: =IF(COUNTIF($AH8:$UG8,G$7)=0,"",COUNTIF($AH8:$UG8,G$7)) -> 11 | H8: =IF(COUNTIF($AH8:$UG8,H$7)=0,"",COUNTIF($AH8:$UG8,H$7)) | I8: =IF(COUNTIF($AH8:$UG8,I$7)=0,"",COUNTIF($AH8:$UG8,I$7)) | J8: =IF(COUNTIF($AH8:$UG8,J$7)=0,"",COUNTIF($AH8:$UG8,J$7)) | K8: =IF(COUNTIF($AH8:$UG8,K$7)=0,"",COUNTIF($AH8:$UG8,K$7)) -> 30 | L8: =IF(COUNTIF($AH8:$UG8,L$7)=0,"",COUNTIF($AH8:$UG8,L$7)) | ... Z8: =IF(COUNTIF($AH8:$UG8,Z$7)=0,"",COUNTIF($AH8:$UG8,Z$7)) | AA8: =BV8 -> Yes | AB8: =EY8 -> 0 | AC8: =IF(SUM(E8:Z8)=0,"",SUM(E8:Z8)) -> 172 | AD8: =IF(SUM(E8:Z8)>=1,AC8-SUM(V8:X8),"") -> 168 | AE8: =IF(COUNTA(AH8:UI8)=0,"",IF(COUNTA(AH8:UI8)=0,0,AG55)) -> 46 | AF8: =IF(AE8="","",AE8/((COUNTA(AH8:BU8)+COUNTA(BW8:EX8)+COUNTA(EZ8:ZYQ8))/4)) -> 1.5206612 | AG8: =IF(AD8="","",AD8/AC8) -> 0.97674419 | AH8: PY | AI8: PY | AJ8: PY | AK8: PY | AL8: PY | AM8: PY | AN8: PY | AO8: PY | AP8: PY | AQ8: GO | AR8: PY | AS8: PY | AT8: PY | AU8: PY | AV8: PY | AW8: PY | AX8: PY | AY8: CES | AZ8: PY | BA8: PY | BB8: PY | BC8: PY | BD8: PY | BE8: PY | BF8: PY | BG8: CES | BH8: PY | BI8: PY | BJ8: PY | BK8: PY | BL8: PY | BM8: PY | BN8: PY | BO8: CES | BP8: PY | BQ8: PY | BR8: PY | BS8: PY | BT8: PY | BU8: PY | BV8: Yes | BW8: PY | BX8: CES | BY8: PY | BZ8: PY | CA8: PY | CB8: PY | CC8: PY | CD8: PY | CE8: PY | CF8: PY | CG8: PY | CH8: PY | CI8: PY | CJ8: PY | CK8: PY | CL8: PY | CM8: PY | CN8: CES | CO8: PY | CP8: PY | CQ8: NY | CR8: NY | CS8: NY | CT8: NY | CU8: NY | CV8: CES | CW8: NY | CX8: NY | CY8: PS | CZ8: PS | DA8: PS | DB8: PS | DC8: PS | DD8: CES | DE8: PS | DF8: PS | DG8: PS | DH8: CES | DI8: PS | DJ8: PS | DK8: PS | DL8: CES | DM8: PS | DN8: PS | DO8: PS | DP8: CES | DQ8: PS | DR8: PS | DS8: PS | DT8: CES | DU8: PS | DV8: PS | DW8: MTP | DX8: MTP | DY8: MTP | DZ8: MTP | EA8: MTP | EB8: CES | EC8: MTP | ED8: MTP | EE8: SB | EF8: CES | EG8: SB | EH8: SB | EI8: SB | EJ8: CES | EK8: SB | EL8: SB | EM8: SB | EN8: CES | EO8: SB | EP8: SB | EQ8: DS | ER8: CES | ES8: DS | ET8: DS | EU8: DS | EV8: CES | EW8: DS | EX8: DS | EZ8: DS | FA8: CES | FB8: DS | FC8: DS | FD8: DS | FE8: CES | FF8: DS | FG8: DS | FH8: IS | FI8: CES | FJ8: IS | FK8: IS | FL8: IS | FM8: CES | FN8: IS | FO8: IS | FP8: Ab | FQ8: Ab | FR8: Ab | FS8: Ab | FT8: AWS | FU8: CES | FV8: AWS | FW8: AWS | FX8: AWS | FY8: CES | FZ8: AWS | GA8: AWS | GB8: AWS | GC8: AWS | GD8: AWS | GE8: AWS | GF8: AWS | GG8: CES | GH8: AWS | GI8: AWS | GJ8: AWS | GK8: CES | GL8: AWS | GM8: AWS | GN8: SQL | GO8: CES | GP8: SQL | GQ8: SQL | GR8: SQL | GS8: CES | GT8: SQL | GU8: SQL | GV8: SQL | GW8: CES | GX8: SQL | GY8: SQL | GZ8: SQL | HA8: CES | HB8: SQL | HC8: SQL | HD8: ML | HE8: CES | HF8: ML | HG8: ML | HH8: ML | HI8: ML | HJ8: ML | HK8: ML | HL8: ML | HM8: ML | HN8: ML | HO8: ML
A9: 2 | B9: 354114 | C9: roshinimanoharan463@gmail.com | D9: Roshini M | E9: =IF(COUNTIF($AH9:$UG9,E$7)=0,"",COUNTIF($AH9:$UG9,E$7)) | F9: =IF(COUNTIF($AH9:$UG9,F$7)=0,"",COUNTIF($AH9:$UG9,F$7)) | G9: =IF(COUNTIF($AH9:$UG9,G$7)=0,"",COUNTIF($AH9:$UG9,G$7)) -> 7 | H9: =IF(COUNTIF($AH9:$UG9,H$7)=0,"",COUNTIF($AH9:$UG9,H$7)) | I9: =IF(COUNTIF($AH9:$UG9,I$7)=0,"",COUNTIF($AH9:$UG9,I$7)) | J9: =IF(COUNTIF($AH9:$UG9,J$7)=0,"",COUNTIF($AH9:$UG9,J$7)) | K9: =IF(COUNTIF($AH9:$UG9,K$7)=0,"",COUNTIF($AH9:$UG9,K$7)) -> 28 | L9: =IF(COUNTIF($AH9:$UG9,L$7)=0,"",COUNTIF($AH9:$UG9,L$7)) | ... Z9: =IF(COUNTIF($AH9:$UG9,Z$7)=0,"",COUNTIF($AH9:$UG9,Z$7)) | AA9: =BV9 -> Yes | AB9: =EY9 -> 0 | AC9: =IF(SUM(E9:Z9)=0,"",SUM(E9:Z9)) -> 172 | AD9: =IF(SUM(E9:Z9)>=1,AC9-SUM(V9:X9),"") -> 147 | AE9: =IF(COUNTA(AH9:UI9)=0,"",IF(COUNTA(AH9:UI9)=0,0,AG57)) -> 41 | AF9: =IF(AE9="","",AE9/((COUNTA(AH9:BU9)+COUNTA(BW9:EX9)+COUNTA(EZ9:#REF!))/4)) -> 1.3553719 | AG9: =IF(AD9="","",AD9/AC9) -> 0.85465116 | AH9: PY | AI9: PY | AJ9: PY | AK9: PY | AL9: PY | AM9: PY | AN9: PY | AO9: PY | AP9: PY | AQ9: GO | AR9: PY | AS9: PY | AT9: Ab | AU9: Ab | AV9: Ab | AW9: Ab | AX9: PY | AY9: CES | AZ9: PY | BA9: PY | BB9: PY | BC9: PY | BD9: PY | BE9: PY | BF9: PY | BG9: CES | BH9: PY | BI9: PY | BJ9: Ab | BK9: Ab | BL9: Ab | BM9: Ab | BN9: PY | BO9: CES | BP9: PY | BQ9: PY | BR9: PY | BS9: PY | BT9: PY | BU9: PY | BV9: Yes | BW9: PY | BX9: CES | BY9: PY | BZ9: PY | CA9: PY | CB9: PY | CC9: PY | CD9: PY | CE9: PY | CF9: PY | CG9: PY | CH9: PY | CI9: Ab | CJ9: Ab | CK9: Ab | CL9: Ab | CM9: PY | CN9: CES | CO9: PY | CP9: PY | CQ9: NY | CR9: NY | CS9: NY | CT9: NY | CU9: NY | CV9: CES | CW9: NY | CX9: NY | CY9: PS | CZ9: PS | DA9: PS | DB9: PS | DC9: PS | DD9: CES | DE9: PS | DF9: PS | DG9: PS | DH9: CES | DI9: PS | DJ9: PS | DK9: PS | DL9: CES | DM9: PS | DN9: PS | DO9: PS | DP9: PS | DQ9: PS | DR9: PS | DS9: PS | DT9: CES | DU9: PS | DV9: PS | DW9: MTP | DX9: MTP | DY9: MTP | DZ9: MTP | EA9: MTP | EB9: CES | EC9: MTP | ED9: MTP | EE9: SB | EF9: CES | EG9: SB | EH9: SB | EI9: SB | EJ9: CES | EK9: SB | EL9: SB | EM9: SB | EN9: CES | EO9: SB | EP9: SB | EQ9: DS | ER9: CES | ES9: DS | ET9: DS | EU9: Ab | EV9: CES | EW9: DS | EX9: DS | EZ9: DS | FA9: CES | FB9: DS | FC9: DS | FD9: DS | FE9: CES | FF9: DS | FG9: DS | FH9: IS | FI9: CES | FJ9: IS | FK9: IS | FL9: IS | FM9: CES | FN9: IS | FO9: IS | FP9: Ab | FQ9: Ab | FR9: Ab | FS9: Ab | FT9: AWS | FU9: CES | FV9: AWS | FW9: AWS | FX9: AWS | FY9: CES | FZ9: AWS | GA9: AWS | GB9: AWS | GC9: AWS | GD9: AWS | GE9: AWS | GF9: AWS | GG9: CES | GH9: AWS | GI9: AWS | GJ9: AWS | GK9: CES | GL9: AWS | GM9: AWS | GN9: SQL | GO9: CES | GP9: SQL | GQ9: SQL | GR9: Ab | GS9: Ab | GT9: Ab | GU9: Ab | GV9: SQL | GW9: CES | GX9: SQL | GY9: SQL | GZ9: SQL | HA9: CES | HB9: SQL | HC9: SQL | HD9: ML | HE9: CES | HF9: ML | HG9: ML | HH9: Ab | HI9: Ab | HJ9: Ab | HK9: Ab | HL9: ML | HM9: ML | HN9: ML | HO9: ML
A10: 3 | B10: 354882 | C10: anowindeepak@gmail.com | D10: Anowin Deepak J V | E10: =IF(COUNTIF($AH10:$UG10,E$7)=0,"",COUNTIF($AH10:$UG10,E$7)) | F10: =IF(COUNTIF($AH10:$UG10,F$7)=0,"",COUNTIF($AH10:$UG10,F$7)) | G10: =IF(COUNTIF($AH10:$UG10,G$7)=0,"",COUNTIF($AH10:$UG10,G$7)) -> 11 | H10: =IF(COUNTIF($AH10:$UG10,H$7)=0,"",COUNTIF($AH10:$UG10,H$7)) | I10: =IF(COUNTIF($AH10:$UG10,I$7)=0,"",COUNTIF($AH10:$UG10,I$7)) | J10: =IF(COUNTIF($AH10:$UG10,J$7)=0,"",COUNTIF($AH10:$UG10,J$7)) | K10: =IF(COUNTIF($AH10:$UG10,K$7)=0,"",COUNTIF($AH10:$UG10,K$7)) -> 27 | L10: =IF(COUNTIF($AH10:$UG10,L$7)=0,"",COUNTIF($AH10:$UG10,L$7)) | ... Z10: =IF(COUNTIF($AH10:$UG10,Z$7)=0,"",COUNTIF($AH10:$UG10,Z$7)) | AA10: =BV10 -> Yes | AB10: =EY10 -> 0 | AC10: =IF(SUM(E10:Z10)=0,"",SUM(E10:Z10)) -> 172 | AD10: =IF(SUM(E10:Z10)>=1,AC10-SUM(V10:X10),"") -> 155 | AE10: =IF(COUNTA(AH10:UI10)=0,"",IF(COUNTA(AH10:UI10)=0,0,AG58)) -> 43 | AF10: =IF(AE10="","",AE10/((COUNTA(AH10:BU10)+COUNTA(BW10:EX10)+COUNTA(EZ10:#REF!))/4)) -> 1.4214876 | AG10: =IF(AD10="","",AD10/AC10) -> 0.90116279 | AH10: PY | AI10: PY | AJ10: PY | AK10: PY | AL10: PY | AM10: PY | AN10: PY | AO10: PY | AP10: PY | AQ10: GO | AR10: PY | AS10: PY | AT10: PY | AU10: PY | AV10: PY | AW10: PY | AX10: PY | AY10: CES | AZ10: PY | BA10: PY | BB10: PY | BC10: PY | BD10: PY | BE10: PY | BF10: PY | BG10: CES | BH10: PY | BI10: PY | BJ10: PY | BK10: PY | BL10: PY | BM10: PY | BN10: PY | BO10: CES | BP10: PY | BQ10: PY | BR10: PY | BS10: PY | BT10: PY | BU10: PY | BV10: Yes | BW10: PY | BX10: CES | BY10: PY | BZ10: PY | CA10: Ab | CB10: Ab | CC10: Ab | CD10: Ab | CE10: PY | CF10: PY | CG10: PY | CH10: PY | CI10: PY | CJ10: PY | CK10: PY | CL10: PY | CM10: PY | CN10: CES | CO10: PY | CP10: PY | CQ10: NY | CR10: NY | CS10: NY | CT10: NY | CU10: NY | CV10: CES | CW10: NY | CX10: NY | CY10: PS | CZ10: PS | DA10: PS | DB10: PS | DC10: PS | DD10: CES | DE10: PS | DF10: PS | DG10: PS | DH10: CES | DI10: PS | DJ10: PS | DK10: Ab | DL10: Ab | DM10: Ab | DN10: Ab | DO10: PS | DP10: PS | DQ10: PS | DR10: PS | DS10: PS | DT10: CES | DU10: PS | DV10: PS | DW10: MTP | DX10: MTP | DY10: MTP | DZ10: MTP | EA10: Ab | EB10: Ab | EC10: Ab | ED10: Ab | EE10: SB | EF10: CES | EG10: SB | EH10: SB | EI10: SB | EJ10: CES | EK10: SB | EL10: SB | EM10: SB | EN10: CES | EO10: SB | EP10: SB | EQ10: DS | ER10: CES | ES10: DS | ET10: DS | EU10: Ab | EV10: CES | EW10: DS | EX10: DS | EZ10: DS | FA10: CES | FB10: DS | FC10: DS | FD10: DS | FE10: CES | FF10: DS | FG10: DS | FH10: IS | FI10: CES | FJ10: IS | FK10: IS | FL10: IS | FM10: CES | FN10: IS | FO10: IS | FP10: Ab | FQ10: Ab | FR10: Ab | FS10: Ab | FT10: AWS | FU10: CES | FV10: AWS | FW10: AWS | FX10: AWS | FY10: CES | FZ10: AWS | GA10: AWS | GB10: AWS | GC10: AWS | GD10: AWS | GE10: AWS | GF10: AWS | GG10: CES | GH10: AWS | GI10: AWS | GJ10: AWS | GK10: CES | GL10: AWS | GM10: AWS | GN10: SQL | GO10: CES | GP10: SQL | GQ10: SQL | GR10: SQL | GS10: CES | GT10: SQL | GU10: SQL | GV10: SQL | GW10: CES | GX10: SQL | GY10: SQL | GZ10: SQL | HA10: CES | HB10: SQL | HC10: SQL | HD10: ML | HE10: CES | HF10: ML | HG10: ML | HH10: ML | HI10: ML | HJ10: ML | HK10: ML | HL10: ML | HM10: ML | HN10: ML | HO10: ML
A11: 4 | B11: 357569 | C11: ajakash755@gmail.com | D11: Akash N | E11: =IF(COUNTIF($AH11:$UG11,E$7)=0,"",COUNTIF($AH11:$UG11,E$7)) | F11: =IF(COUNTIF($AH11:$UG11,F$7)=0,"",COUNTIF($AH11:$UG11,F$7)) | G11: =IF(COUNTIF($AH11:$UG11,G$7)=0,"",COUNTIF($AH11:$UG11,G$7)) -> 11 | H11: =IF(COUNTIF($AH11:$UG11,H$7)=0,"",COUNTIF($AH11:$UG11,H$7)) | I11: =IF(COUNTIF($AH11:$UG11,I$7)=0,"",COUNTIF($AH11:$UG11,I$7)) | J11: =IF(COUNTIF($AH11:$UG11,J$7)=0,"",COUNTIF($AH11:$UG11,J$7)) | K11: =IF(COUNTIF($AH11:$UG11,K$7)=0,"",COUNTIF($AH11:$UG11,K$7)) -> 29 | L11: =IF(COUNTIF($AH11:$UG11,L$7)=0,"",COUNTIF($AH11:$UG11,L$7)) | ... Z11: =IF(COUNTIF($AH11:$UG11,Z$7)=0,"",COUNTIF($AH11:$UG11,Z$7)) | AA11: =BV11 -> Yes | AB11: =EY11 -> 0 | AC11: =IF(SUM(E11:Z11)=0,"",SUM(E11:Z11)) -> 168 | AD11: =IF(SUM(E11:Z11)>=1,AC11-SUM(V11:X11),"") -> 167 | AE11: =IF(COUNTA(AH11:UI11)=0,"",IF(COUNTA(AH11:UI11)=0,0,AG59)) -> 47 | AF11: =IF(AE11="","",AE11/((COUNTA(AH11:BU11)+COUNTA(BW11:EX11)+COUNTA(EZ11:#REF!))/4)) -> 1.553719 | AG11: =IF(AD11="","",AD11/AC11) -> 0.99404762 | AH11: PY | AI11: PY | AJ11: PY | AK11: PY | AL11: PY | AM11: PY | AN11: PY | AO11: PY | AP11: PY | AQ11: GO | AR11: PY | AS11: PY | AT11: PY | AU11: PY | AV11: PY | AW11: PY | AX11: PY | AY11: CES | AZ11: PY | BA11: PY | BB11: PY | BC11: PY | BD11: PY | BE11: PY | BF11: PY | BG11: CES | BH11: PY | BI11: PY | BJ11: PY | BK11: PY | BL11: PY | BM11: PY | BN11: PY | BO11: CES | BP11: PY | BQ11: PY | BR11: PY | BS11: PY | BT11: PY | BU11: PY | BV11: Yes | BW11: PY | BX11: CES | BY11: PY | BZ11: PY | CA11: PY | CB11: PY | CC11: PY | CD11: PY | CE11: PY | CF11: PY | CG11: PY | CH11: PY | CI11: PY | CJ11: PY | CK11: PY | CL11: PY | CM11: PY | CN11: CES | CO11: PY | CP11: PY | CQ11: NY | CR11: NY | CS11: NY | CT11: NY | CU11: NY | CV11: CES | CW11: NY | CX11: NY | CY11: PS | CZ11: PS | DA11: PS | DB11: PS | DC11: PS | DD11: CES | DE11: PS | DF11: PS | DG11: PS | DH11: CES | DI11: PS | DJ11: PS | DK11: PS | DL11: CES | DM11: PS | DN11: PS | DO11: PS | DP11: PS | DQ11: PS | DR11: PS | DS11: PS | DT11: CES | DU11: PS | DV11: PS | DW11: MTP | DX11: MTP | DY11: MTP | DZ11: MTP | EA11: MTP | EB11: CES | EC11: MTP | ED11: MTP | EE11: SB | EF11: CES | EG11: SB | EH11: SB | EI11: SB | EJ11: CES | EK11: SB | EL11: SB | EM11: SB | EN11: CES | EO11: SB | EP11: SB | EQ11: DS | ER11: CES | ES11: DS | ET11: DS | EU11: Ab | EV11: CES | EW11: DS | EX11: DS | EZ11: DS | FA11: CES | FB11: DS | FC11: DS | FD11: DS | FE11: CES | FF11: DS | FG11: DS | FH11: IS | FI11: CES | FJ11: IS | FK11: IS | FL11: IS | FM11: CES | FN11: IS | FO11: IS | FP11: AWS | FQ11: AWS | FR11: AWS | FS11: AWS | FT11: AWS | FU11: CES | FV11: AWS | FW11: AWS | FX11: AWS | FY11: CES | FZ11: AWS | GA11: AWS | GB11: AWS | GC11: AWS | GD11: AWS | GE11: AWS | GF11: AWS | GG11: CES | GH11: AWS | GI11: AWS | GJ11: AWS | GK11: CES | GL11: AWS | GM11: AWS | GN11: SQL | GO11: CES | GP11: SQL | GQ11: SQL | GR11: SQL | GS11: CES | GT11: SQL | GU11: SQL | GV11: SQL | GW11: CES | GX11: SQL | GY11: SQL | GZ11: SQL | HA11: CES | HB11: SQL | HC11: SQL | HD11: ML | HE11: CES | HF11: ML | HG11: ML | HH11: ML | HI11: ML | HJ11: ML | HK11: ML | HL11: ML | HM11: ML | HN11: ML | HO11: ML
A12: 5 | B12: 357670 | C12: kerthikaa.m@gmail.com | D12: M Kerthikaa | E12: =IF(COUNTIF($AH12:$UG12,E$7)=0,"",COUNTIF($AH12:$UG12,E$7)) | F12: =IF(COUNTIF($AH12:$UG12,F$7)=0,"",COUNTIF($AH12:$UG12,F$7)) | G12: =IF(COUNTIF($AH12:$UG12,G$7)=0,"",COUNTIF($AH12:$UG12,G$7)) -> 7 | H12: =IF(COUNTIF($AH12:$UG12,H$7)=0,"",COUNTIF($AH12:$UG12,H$7)) | I12: =IF(COUNTIF($AH12:$UG12,I$7)=0,"",COUNTIF($AH12:$UG12,I$7)) | J12: =IF(COUNTIF($AH12:$UG12,J$7)=0,"",COUNTIF($AH12:$UG12,J$7)) | K12: =IF(COUNTIF($AH12:$UG12,K$7)=0,"",COUNTIF($AH12:$UG12,K$7)) -> 24 | L12: =IF(COUNTIF($AH12:$UG12,L$7)=0,"",COUNTIF($AH12:$UG12,L$7)) | ... Z12: =IF(COUNTIF($AH12:$UG12,Z$7)=0,"",COUNTIF($AH12:$UG12,Z$7)) | AA12: =BV12 -> Yes | AB12: =EY12 -> 0 | AC12: =IF(SUM(E12:Z12)=0,"",SUM(E12:Z12)) -> 171 | AD12: =IF(SUM(E12:Z12)>=1,AC12-SUM(V12:X12),"") -> 146 | AE12: =IF(COUNTA(AH12:UI12)=0,"",IF(COUNTA(AH12:UI12)=0,0,AG60)) -> 41 | AF12: =IF(AE12="","",AE12/((COUNTA(AH12:BU12)+COUNTA(BW12:EX12)+COUNTA(EZ12:#REF!))/4)) -> 1.3553719 | AG12: =IF(AD12="","",AD12/AC12) -> 0.85380117 | AH12: PY | AI12: PY | AJ12: PY | AK12: PY | AL12: PY | AM12: PY | AN12: PY | AO12: PY | AP12: PY | AQ12: GO | AR12: PY | AS12: PY | AT12: PY | AU12: PY | AV12: PY | AW12: PY | AX12: PY | AY12: CES | AZ12: PY | BA12: PY | BB12: PY | BC12: PY | BD12: PY | BE12: PY | BF12: PY | BG12: CES | BH12: PY | BI12: PY | BJ12: PY | BK12: PY | BL12: PY | BM12: PY | BN12: PY | BO12: CES | BP12: PY | BQ12: PY | BR12: PY | BS12: PY | BT12: PY | BU12: PY | BV12: Yes | BW12: PY | BX12: CES | BY12: PY | BZ12: PY | CA12: PY | CB12: PY | CC12: PY | CD12: PY | CE12: PY | CF12: PY | CG12: PY | CH12: PY | CI12: PY | CJ12: PY | CK12: PY | CL12: PY | CM12: Ab | CN12: Ab | CO12: Ab | CP12: Ab | CQ12: NY | CR12: NY | CS12: NY | CT12: NY | CU12: Ab | CV12: Ab | CW12: Ab | CX12: Ab | CY12: PS | CZ12: PS | DA12: PS | DB12: PS | DC12: Ab | DD12: Ab | DE12: Ab | DF12: Ab | DG12: PS | DH12: CES | DI12: PS | DJ12: PS | DK12: PS | DL12: CES | DM12: PS | DN12: PS | DO12: PS | DP12: PS | DQ12: PS | DR12: PS | DS12: PS | DT12: CES | DU12: PS | DV12: PS | DW12: MTP | DX12: MTP | DY12: MTP | DZ12: MTP | EA12: MTP | EB12: CES | EC12: MTP | ED12: MTP | EE12: SB | EF12: CES | EG12: SB | EH12: SB | EI12: SB | EJ12: CES | EK12: SB | EL12: SB | EM12: SB | EN12: CES | EO12: SB | EP12: SB | EQ12: DS | ER12: CES | ES12: DS | ET12: DS | EU12: Ab | EV12: CES | EW12: DS | EX12: DS | EZ12: DS | FA12: CES | FB12: DS | FC12: DS | FD12: DS | FE12: CES | FF12: DS | FG12: DS | FH12: IS | FI12: CES | FJ12: IS | FK12: IS | FL12: IS | FM12: CES | FN12: IS | FO12: IS | FP12: AWS | FQ12: AWS | FR12: AWS | FS12: AWS | FT12: AWS | FU12: CES | FV12: AWS | FW12: AWS | FX12: AWS | FY12: CES | FZ12: AWS | GA12: AWS | GB12: AWS | GC12: AWS | GD12: AWS | GE12: AWS | GF12: Ab | GG12: Ab | GH12: Ab | GI12: Ab | GJ12: AWS | GK12: CES | GL12: AWS | GM12: AWS | GN12: Ab | GO12: Ab | GP12: Ab | GQ12: Ab | GR12: SQL | GS12: CES | GT12: SQL | GU12: SQL | GV12: SQL | GW12: CES | GX12: SQL | GY12: SQL | GZ12: SQL | HA12: CES | HB12: SQL | HC12: SQL | HD12: ML | HE12: CES | HF12: ML | HG12: ML | HH12: Ab | HI12: Ab | HJ12: Ab | HK12: Ab | HL12: ML | HM12: ML | HN12: ML | HO12: ML
A13: 6 | B13: 358104 | C13: jvishal12998@gmail.com | D13: Vishal C J | E13: =IF(COUNTIF($AH13:$UG13,E$7)=0,"",COUNTIF($AH13:$UG13,E$7)) | F13: =IF(COUNTIF($AH13:$UG13,F$7)=0,"",COUNTIF($AH13:$UG13,F$7)) | G13: =IF(COUNTIF($AH13:$UG13,G$7)=0,"",COUNTIF($AH13:$UG13,G$7)) -> 7 | H13: =IF(COUNTIF($AH13:$UG13,H$7)=0,"",COUNTIF($AH13:$UG13,H$7)) | I13: =IF(COUNTIF($AH13:$UG13,I$7)=0,"",COUNTIF($AH13:$UG13,I$7)) | J13: =IF(COUNTIF($AH13:$UG13,J$7)=0,"",COUNTIF($AH13:$UG13,J$7)) | K13: =IF(COUNTIF($AH13:$UG13,K$7)=0,"",COUNTIF($AH13:$UG13,K$7)) -> 28 | L13: =IF(COUNTIF($AH13:$UG13,L$7)=0,"",COUNTIF($AH13:$UG13,L$7)) | ... Z13: =IF(COUNTIF($AH13:$UG13,Z$7)=0,"",COUNTIF($AH13:$UG13,Z$7)) | AA13: =BV13 -> Yes | AB13: =EY13 -> 0 | AC13: =IF(SUM(E13:Z13)=0,"",SUM(E13:Z13)) -> 175 | AD13: =IF(SUM(E13:Z13)>=1,AC13-SUM(V13:X13),"") -> 158 | AE13: =IF(COUNTA(AH13:UI13)=0,"",IF(COUNTA(AH13:UI13)=0,0,AG61)) -> 43 | AF13: =IF(AE13="","",AE13/((COUNTA(AH13:BU13)+COUNTA(BW13:EX13)+COUNTA(EZ13:#REF!))/4)) -> 1.4214876 | AG13: =IF(AD13="","",AD13/AC13) -> 0.90285714 | AH13: PY | AI13: PY | AJ13: PY | AK13: PY | AL13: PY | AM13: PY | AN13: PY | AO13: PY | AP13: PY | AQ13: GO | AR13: PY | AS13: PY | AT13: PY | AU13: PY | AV13: PY | AW13: PY | AX13: PY | AY13: CES | AZ13: PY | BA13: PY | BB13: PY | BC13: PY | BD13: PY | BE13: PY | BF13: PY | BG13: CES | BH13: PY | BI13: PY | BJ13: Ab | BK13: Ab | BL13: Ab | BM13: Ab | BN13: PY | BO13: CES | BP13: PY | BQ13: PY | BR13: PY | BS13: PY | BT13: PY | BU13: PY | BV13: Yes | BW13: PY | BX13: CES | BY13: PY | BZ13: PY | CA13: PY | CB13: PY | CC13: PY | CD13: PY | CE13: PY | CF13: PY | CG13: PY | CH13: PY | CI13: PY | CJ13: PY | CK13: PY | CL13: PY | CM13: PY | CN13: CES | CO13: PY | CP13: PY | CQ13: NY | CR13: NY | CS13: NY | CT13: NY | CU13: NY | CV13: CES | CW13: NY | CX13: NY | CY13: PS | CZ13: PS | DA13: PS | DB13: PS | DC13: PS | DD13: CES | DE13: PS | DF13: PS | DG13: PS | DH13: CES | DI13: PS | DJ13: PS | DK13: PS | DL13: CES | DM13: PS | DN13: PS | DO13: PS | DP13: PS | DQ13: PS | DR13: PS | DS13: PS | DT13: CES | DU13: PS | DV13: PS | DW13: MTP | DX13: MTP | DY13: MTP | DZ13: MTP | EA13: MTP | EB13: CES | EC13: MTP | ED13: MTP | EE13: SB | EF13: CES | EG13: SB | EH13: SB | EI13: SB | EJ13: CES | EK13: SB | EL13: SB | EM13: SB | EN13: CES | EO13: SB | EP13: SB | EQ13: DS | ER13: CES | ES13: DS | ET13: DS | EU13: Ab | EV13: CES | EW13: DS | EX13: DS | EZ13: DS | FA13: CES | FB13: DS | FC13: DS | FD13: DS | FE13: CES | FF13: DS | FG13: DS | FH13: IS | FI13: CES | FJ13: IS | FK13: IS | FL13: IS | FM13: CES | FN13: IS | FO13: IS | FP13: Ab | FQ13: Ab | FR13: Ab | FS13: Ab | FT13: AWS | FU13: CES | FV13: AWS | FW13: AWS | FX13: Ab | FY13: Ab | FZ13: Ab | GA13: Ab | GB13: AWS | GC13: AWS | GD13: AWS | GE13: AWS | GF13: AWS | GG13: CES | GH13: AWS | GI13: AWS | GJ13: AWS | GK13: CES | GL13: AWS | GM13: AWS | GN13: SQL | GO13: CES | GP13: SQL | GQ13: SQL | GR13: SQL | GS13: CES | GT13: SQL | GU13: SQL | GV13: SQL | GW13: CES | GX13: SQL | GY13: SQL | GZ13: SQL | HA13: CES | HB13: SQL | HC13: SQL | HD13: ML | HE13: CES | HF13: ML | HG13: ML | HH13: Ab | HI13: Ab | HJ13: Ab | HK13: Ab | HL13: ML | HM13: ML | HN13: ML | HO13: ML
A14: 7 | B14: 358147 | C14: buvaneshbuvi19@gmail.com | D14: Buvanesh M | E14: =IF(COUNTIF($AH14:$UG14,E$7)=0,"",COUNTIF($AH14:$UG14,E$7)) | F14: =IF(COUNTIF($AH14:$UG14,F$7)=0,"",COUNTIF($AH14:$UG14,F$7)) | G14: =IF(COUNTIF($AH14:$UG14,G$7)=0,"",COUNTIF($AH14:$UG14,G$7)) -> 11 | H14: =IF(COUNTIF($AH14:$UG14,H$7)=0,"",COUNTIF($AH14:$UG14,H$7)) | I14: =IF(COUNTIF($AH14:$UG14,I$7)=0,"",COUNTIF($AH14:$UG14,I$7)) | J14: =IF(COUNTIF($AH14:$UG14,J$7)=0,"",COUNTIF($AH14:$UG14,J$7)) | K14: =IF(COUNTIF($AH14:$UG14,K$7)=0,"",COUNTIF($AH14:$UG14,K$7)) -> 27 | L14: =IF(COUNTIF($AH14:$UG14,L$7)=0,"",COUNTIF($AH14:$UG14,L$7)) | ... Z14: =IF(COUNTIF($AH14:$UG14,Z$7)=0,"",COUNTIF($AH14:$UG14,Z$7)) | AA14: =BV14 -> Yes | AB14: =EY14 -> 0 | AC14: =IF(SUM(E14:Z14)=0,"",SUM(E14:Z14)) -> 168 | AD14: =IF(SUM(E14:Z14)>=1,AC14-SUM(V14:X14),"") -> 152 | AE14: =IF(COUNTA(AH14:UI14)=0,"",IF(COUNTA(AH14:UI14)=0,0,AG62)) -> 43 | AF14: =IF(AE14="","",AE14/((COUNTA(AH14:BU14)+COUNTA(BW14:EX14)+COUNTA(EZ14:#REF!))/4)) -> 1.4214876 | AG14: =IF(AD14="","",AD14/AC14) -> 0.9047619 | AH14: PY | AI14: PY | AJ14: PY | AK14: PY | AL14: PY | AM14: PY | AN14: PY | AO14: PY | AP14: PY | AQ14: GO | AR14: PY | AS14: PY | AT14: Ab | AU14: Ab | AV14: Ab | AW14: Ab | AX14: PY | AY14: CES | AZ14: PY | BA14: PY | BB14: PY | BC14: PY | BD14: PY | BE14: PY | BF14: PY | BG14: CES | BH14: PY | BI14: PY | BJ14: PY | BK14: PY | BL14: PY | BM14: PY | BN14: PY | BO14: CES | BP14: PY | BQ14: PY | BR14: PY | BS14: PY | BT14: PY | BU14: PY | BV14: Yes | BW14: PY | BX14: CES | BY14: PY | BZ14: PY | CA14: PY | CB14: PY | CC14: PY | CD14: PY | CE14: PY | CF14: PY | CG14: PY | CH14: PY | CI14: PY | CJ14: PY | CK14: PY | CL14: PY | CM14: Ab | CN14: Ab | CO14: Ab | CP14: Ab | CQ14: NY | CR14: NY | CS14: NY | CT14: NY | CU14: NY | CV14: CES | CW14: NY | CX14: NY | CY14: Ab | CZ14: Ab | DA14: Ab | DB14: Ab | DC14: PS | DD14: CES | DE14: PS | DF14: PS | DG14: PS | DH14: CES | DI14: PS | DJ14: PS | DK14: PS | DL14: CES | DM14: PS | DN14: PS | DO14: PS | DP14: PS | DQ14: PS | DR14: PS | DS14: PS | DT14: CES | DU14: PS | DV14: PS | DW14: MTP | DX14: MTP | DY14: MTP | DZ14: MTP | EA14: MTP | EB14: CES | EC14: MTP | ED14: MTP | EE14: SB | EF14: CES | EG14: SB | EH14: SB | EI14: SB | EJ14: CES | EK14: SB | EL14: SB | EM14: SB | EN14: CES | EO14: SB | EP14: SB | EQ14: DS | ER14: CES | ES14: DS | ET14: DS | EU14: DS | EV14: CES | EW14: DS | EX14: DS | EZ14: DS | FA14: CES | FB14: DS | FC14: DS | FD14: DS | FE14: CES | FF14: DS | FG14: DS | FH14: IS | FI14: CES | FJ14: IS | FK14: IS | FL14: IS | FM14: CES | FN14: IS | FO14: IS | FP14: AWS | FQ14: AWS | FR14: AWS | FS14: AWS | FT14: AWS | FU14: CES | FV14: AWS | FW14: AWS | FX14: AWS | FY14: CES | FZ14: AWS | GA14: AWS | GB14: AWS | GC14: AWS | GD14: AWS | GE14: AWS | GF14: AWS | GG14: CES | GH14: AWS | GI14: AWS | GJ14: AWS | GK14: CES | GL14: AWS | GM14: AWS | GN14: Ab | GO14: Ab | GP14: Ab | GQ14: Ab | GR14: SQL | GS14: CES | GT14: SQL | GU14: SQL | GV14: SQL | GW14: CES | GX14: SQL | GY14: SQL | GZ14: SQL | HA14: CES | HB14: SQL | HC14: SQL | HD14: ML | HE14: CES | HF14: ML | HG14: ML | HH14: ML | HI14: ML | HJ14: ML | HK14: ML | HL14: ML | HM14: ML | HN14: ML | HO14: ML
A15: 8 | B15: 358516 | C15: megalameki@gmail.com | D15: Megala | E15: =IF(COUNTIF($AH15:$UG15,E$7)=0,"",COUNTIF($AH15:$UG15,E$7)) | F15: =IF(COUNTIF($AH15:$UG15,F$7)=0,"",COUNTIF($AH15:$UG15,F$7)) | G15: =IF(COUNTIF($AH15:$UG15,G$7)=0,"",COUNTIF($AH15:$UG15,G$7)) -> 3 | H15: =IF(COUNTIF($AH15:$UG15,H$7)=0,"",COUNTIF($AH15:$UG15,H$7)) | I15: =IF(COUNTIF($AH15:$UG15,I$7)=0,"",COUNTIF($AH15:$UG15,I$7)) | J15: =IF(COUNTIF($AH15:$UG15,J$7)=0,"",COUNTIF($AH15:$UG15,J$7)) | K15: =IF(COUNTIF($AH15:$UG15,K$7)=0,"",COUNTIF($AH15:$UG15,K$7)) -> 17 | L15: =IF(COUNTIF($AH15:$UG15,L$7)=0,"",COUNTIF($AH15:$UG15,L$7)) | ... Z15: =IF(COUNTIF($AH15:$UG15,Z$7)=0,"",COUNTIF($AH15:$UG15,Z$7)) | AA15: =BV15 -> Yes | AB15: =EY15 -> 0 | AC15: =IF(SUM(E15:Z15)=0,"",SUM(E15:Z15)) -> 181 | AD15: =IF(SUM(E15:Z15)>=1,AC15-SUM(V15:X15),"") -> 120 | AE15: =IF(COUNTA(AH15:UI15)=0,"",IF(COUNTA(AH15:UI15)=0,0,AG63)) -> 32 | AF15: =IF(AE15="","",AE15/((COUNTA(AH15:BU15)+COUNTA(BW15:EX15)+COUNTA(EZ15:#REF!))/4)) -> 1.0578512 | AG15: =IF(AD15="","",AD15/AC15) -> 0.66298343 | AH15: PY | AI15: PY | AJ15: PY | AK15: PY | AL15: PY | AM15: PY | AN15: PY | AO15: PY | AP15: PY | AQ15: GO | AR15: PY | AS15: PY | AT15: PY | AU15: PY | AV15: PY | AW15: PY | AX15: PY | AY15: CES | AZ15: PY | BA15: PY | BB15: PY | BC15: PY | BD15: PY | BE15: PY | BF15: PY | BG15: CES | BH15: PY | BI15: PY | BJ15: PY | BK15: PY | BL15: PY | BM15: PY | BN15: PY | BO15: CES | BP15: PY | BQ15: PY | BR15: PY | BS15: PY | BT15: PY | BU15: PY | BV15: Yes | BW15: PY | BX15: CES | BY15: PY | BZ15: PY | CA15: PY | CB15: PY | CC15: PY | CD15: PY | CE15: PY | CF15: PY | CG15: PY | CH15: PY | CI15: PY | CJ15: PY | CK15: PY | CL15: PY | CM15: PY | CN15: CES | CO15: PY | CP15: PY | CQ15: NY | CR15: NY | CS15: NY | CT15: NY | CU15: Ab | CV15: Ab | CW15: Ab | CX15: Ab | CY15: PS | CZ15: PS | DA15: PS | DB15: PS | DC15: PS | DD15: CES | DE15: PS | DF15: PS | DG15: PS | DH15: CES | DI15: PS | DJ15: PS | DK15: PS | DL15: CES | DM15: PS | DN15: PS | DO15: PS | DP15: PS | DQ15: PS | DR15: PS | DS15: Ab | DT15: Ab | DU15: Ab | DV15: Ab | DW15: MTP | DX15: MTP | DY15: MTP | DZ15: MTP | EA15: Ab | EB15: Ab | EC15: Ab | ED15: Ab | EE15: Ab | EF15: Ab | EG15: Ab | EH15: Ab | EI15: Ab | EJ15: Ab | EK15: Ab | EL15: Ab | EM15: Ab | EN15: Ab | EO15: Ab | EP15: Ab | EQ15: Ab | ER15: Ab | ES15: Ab | ET15: Ab | EU15: Ab | EV15: CES | EW15: DS | EX15: DS | EZ15: DS | FA15: CES | FB15: DS | FC15: DS | FD15: Ab | FE15: Ab | FF15: Ab | FG15: Ab | FH15: IS | FI15: CES | FJ15: IS | FK15: IS | FL15: Ab | FM15: Ab | FN15: Ab | FO15: Ab | FP15: Ab | FQ15: Ab | FR15: Ab | FS15: Ab | FT15: Ab | FU15: Ab | FV15: Ab | FW15: Ab | FX15: Ab | FY15: Ab | FZ15: Ab | GA15: Ab | GB15: AWS | GC15: AWS | GD15: AWS | GE15: AWS | GF15: AWS | GG15: CES | GH15: AWS | GI15: AWS | GJ15: Ab | GK15: Ab | GL15: Ab | GM15: Ab | GN15: SQL | GO15: CES | GP15: SQL | GQ15: SQL | GR15: SQL | GS15: CES | GT15: SQL | GU15: SQL | GV15: SQL | GW15: CES | GX15: SQL | GY15: SQL | GZ15: SQL | HA15: CES | HB15: SQL | HC15: SQL | HD15: ML | HE15: CES | HF15: ML | HG15: ML | HH15: Ab | HI15: Ab | HJ15: Ab | HK15: Ab | HL15: Ab | HM15: Ab | HN15: Ab | HO15: Ab
A16: 9 | B16: 359881 | C16: vishwap2802@gmail.com | D16: Vishva P | E16: =IF(COUNTIF($AH16:$UG16,E$7)=0,"",COUNTIF($AH16:$UG16,E$7)) | F16: =IF(COUNTIF($AH16:$UG16,F$7)=0,"",COUNTIF($AH16:$UG16,F$7)) | G16: =IF(COUNTIF($AH16:$UG16,G$7)=0,"",COUNTIF($AH16:$UG16,G$7)) -> 11 | H16: =IF(COUNTIF($AH16:$UG16,H$7)=0,"",COUNTIF($AH16:$UG16,H$7)) | I16: =IF(COUNTIF($AH16:$UG16,I$7)=0,"",COUNTIF($AH16:$UG16,I$7)) | J16: =IF(COUNTIF($AH16:$UG16,J$7)=0,"",COUNTIF($AH16:$UG16,J$7)) | K16: =IF(COUNTIF($AH16:$UG16,K$7)=0,"",COUNTIF($AH16:$UG16,K$7)) -> 29 | L16: =IF(COUNTIF($AH16:$UG16,L$7)=0,"",COUNTIF($AH16:$UG16,L$7)) | ... Z16: =IF(COUNTIF($AH16:$UG16,Z$7)=0,"",COUNTIF($AH16:$UG16,Z$7)) | AA16: =BV16 -> Yes | AB16: =EY16 -> 0 | AC16: =IF(SUM(E16:Z16)=0,"",SUM(E16:Z16)) -> 168 | AD16: =IF(SUM(E16:Z16)>=1,AC16-SUM(V16:X16),"") -> 168 | AE16: =IF(COUNTA(AH16:UI16)=0,"",IF(COUNTA(AH16:UI16)=0,0,AG64)) -> 47 | AF16: =IF(AE16="","",AE16/((COUNTA(AH16:BU16)+COUNTA(BW16:EX16)+COUNTA(EZ16:#REF!))/4)) -> 1.553719 | AG16: =IF(AD16="","",AD16/AC16) -> 1 | AH16: PY | AI16: PY | AJ16: PY | AK16: PY | AL16: PY | AM16: PY | AN16: PY | AO16: PY | AP16: PY | AQ16: GO | AR16: PY | AS16: PY | AT16: PY | AU16: PY | AV16: PY | AW16: PY | AX16: PY | AY16: CES | AZ16: PY | BA16: PY | BB16: PY | BC16: PY | BD16: PY | BE16: PY | BF16: PY | BG16: CES | BH16: PY | BI16: PY | BJ16: PY | BK16: PY | BL16: PY | BM16: PY | BN16: PY | BO16: CES | BP16: PY | BQ16: PY | BR16: PY | BS16: PY | BT16: PY | BU16: PY | BV16: Yes | BW16: PY | BX16: CES | BY16: PY | BZ16: PY | CA16: PY | CB16: PY | CC16: PY | CD16: PY | CE16: PY | CF16: PY | CG16: PY | CH16: PY | CI16: PY | CJ16: PY | CK16: PY | CL16: PY | CM16: PY | CN16: CES | CO16: PY | CP16: PY | CQ16: NY | CR16: NY | CS16: NY | CT16: NY | CU16: NY | CV16: CES | CW16: NY | CX16: NY | CY16: PS | CZ16: PS | DA16: PS | DB16: PS | DC16: PS | DD16: CES | DE16: PS | DF16: PS | DG16: PS | DH16: CES | DI16: PS | DJ16: PS | DK16: PS | DL16: CES | DM16: PS | DN16: PS | DO16: PS | DP16: PS | DQ16: PS | DR16: PS | DS16: PS | DT16: CES | DU16: PS | DV16: PS | DW16: MTP | DX16: MTP | DY16: MTP | DZ16: MTP | EA16: MTP | EB16: CES | EC16: MTP | ED16: MTP | EE16: SB | EF16: CES | EG16: SB | EH16: SB | EI16: SB | EJ16: CES | EK16: SB | EL16: SB | EM16: SB | EN16: CES | EO16: SB | EP16: SB | EQ16: DS | ER16: CES | ES16: DS | ET16: DS | EU16: SB | EV16: CES | EW16: DS | EX16: DS | EZ16: DS | FA16: CES | FB16: DS | FC16: DS | FD16: DS | FE16: CES | FF16: DS | FG16: DS | FH16: IS | FI16: CES | FJ16: IS | FK16: IS | FL16: IS | FM16: CES | FN16: IS | FO16: IS | FP16: AWS | FQ16: AWS | FR16: AWS | FS16: AWS | FT16: AWS | FU16: CES | FV16: AWS | FW16: AWS | FX16: AWS | FY16: CES | FZ16: AWS | GA16: AWS | GB16: AWS | GC16: AWS | GD16: AWS | GE16: AWS | GF16: AWS | GG16: CES | GH16: AWS | GI16: AWS | GJ16: AWS | GK16: CES | GL16: AWS | GM16: AWS | GN16: SQL | GO16: CES | GP16: SQL | GQ16: SQL | GR16: SQL | GS16: CES | GT16: SQL | GU16: SQL | GV16: SQL | GW16: CES | GX16: SQL | GY16: SQL | GZ16: SQL | HA16: CES | HB16: SQL | HC16: SQL | HD16: ML | HE16: CES | HF16: ML | HG16: ML | HH16: ML | HI16: ML | HJ16: ML | HK16: ML | HL16: ML | HM16: ML | HN16: ML | HO16: ML
A17: 10 | B17: 359935 | C17: purushoth1727@gmail.com | D17: Purushothaman Vengidesan | E17: =IF(COUNTIF($AH17:$UG17,E$7)=0,"",COUNTIF($AH17:$UG17,E$7)) | F17: =IF(COUNTIF($AH17:$UG17,F$7)=0,"",COUNTIF($AH17:$UG17,F$7)) | G17: =IF(COUNTIF($AH17:$UG17,G$7)=0,"",COUNTIF($AH17:$UG17,G$7)) -> 11 | H17: =IF(COUNTIF($AH17:$UG17,H$7)=0,"",COUNTIF($AH17:$UG17,H$7)) | I17: =IF(COUNTIF($AH17:$UG17,I$7)=0,"",COUNTIF($AH17:$UG17,I$7)) | J17: =IF(COUNTIF($AH17:$UG17,J$7)=0,"",COUNTIF($AH17:$UG17,J$7)) | K17: =IF(COUNTIF($AH17:$UG17,K$7)=0,"",COUNTIF($AH17:$UG17,K$7)) -> 27 | L17: =IF(COUNTIF($AH17:$UG17,L$7)=0,"",COUNTIF($AH17:$UG17,L$7)) | ... Z17: =IF(COUNTIF($AH17:$UG17,Z$7)=0,"",COUNTIF($AH17:$UG17,Z$7)) | AA17: =BV17 -> Yes | AB17: =EY17 -> 0 | AC17: =IF(SUM(E17:Z17)=0,"",SUM(E17:Z17)) -> 172 | AD17: =IF(SUM(E17:Z17)>=1,AC17-SUM(V17:X17),"") -> 156 | AE17: =IF(COUNTA(AH17:UI17)=0,"",IF(COUNTA(AH17:UI17)=0,0,AG65)) -> 43 | AF17: =IF(AE17="","",AE17/((COUNTA(AH17:BU17)+COUNTA(BW17:EX17)+COUNTA(EZ17:#REF!))/4)) -> 1.4214876 | AG17: =IF(AD17="","",AD17/AC17) -> 0.90697674 | AH17: PY | AI17: PY | AJ17: PY | AK17: PY | AL17: PY | AM17: PY | AN17: PY | AO17: PY | AP17: PY | AQ17: GO | AR17: PY | AS17: PY | AT17: PY | AU17: PY | AV17: PY | AW17: PY | AX17: Ab | AY17: Ab | AZ17: Ab | BA17: Ab | BB17: PY | BC17: PY | BD17: PY | BE17: PY | BF17: PY | BG17: CES | BH17: PY | BI17: PY | BJ17: PY | BK17: PY | BL17: PY | BM17: PY | BN17: PY | BO17: CES | BP17: PY | BQ17: PY | BR17: PY | BS17: PY | BT17: PY | BU17: PY | BV17: Yes | BW17: PY | BX17: CES | BY17: PY | BZ17: PY | CA17: Ab | CB17: Ab | CC17: Ab | CD17: Ab | CE17: PY | CF17: PY | CG17: PY | CH17: PY | CI17: PY | CJ17: PY | CK17: PY | CL17: PY | CM17: Ab | CN17: Ab | CO17: Ab | CP17: Ab | CQ17: NY | CR17: NY | CS17: NY | CT17: NY | CU17: NY | CV17: CES | CW17: NY | CX17: NY | CY17: PS | CZ17: PS | DA17: PS | DB17: PS | DC17: PS | DD17: CES | DE17: PS | DF17: PS | DG17: PS | DH17: CES | DI17: PS | DJ17: PS | DK17: PS | DL17: CES | DM17: PS | DN17: PS | DO17: PS | DP17: PS | DQ17: PS | DR17: PS | DS17: PS | DT17: CES | DU17: PS | DV17: PS | DW17: MTP | DX17: MTP | DY17: MTP | DZ17: MTP | EA17: MTP | EB17: CES | EC17: MTP | ED17: MTP | EE17: SB | EF17: CES | EG17: SB | EH17: SB | EI17: SB | EJ17: CES | EK17: SB | EL17: SB | EM17: SB | EN17: CES | EO17: SB | EP17: SB | EQ17: DS | ER17: CES | ES17: DS | ET17: DS | EU17: SB | EV17: CES | EW17: DS | EX17: DS | EZ17: DS | FA17: CES | FB17: DS | FC17: DS | FD17: DS | FE17: CES | FF17: DS | FG17: DS | FH17: IS | FI17: CES | FJ17: IS | FK17: IS | FL17: IS | FM17: CES | FN17: IS | FO17: IS | FP17: Ab | FQ17: Ab | FR17: Ab | FS17: Ab | FT17: AWS | FU17: CES | FV17: AWS | FW17: AWS | FX17: AWS | FY17: CES | FZ17: AWS | GA17: AWS | GB17: AWS | GC17: AWS | GD17: AWS | GE17: AWS | GF17: AWS | GG17: CES | GH17: AWS | GI17: AWS | GJ17: AWS | GK17: CES | GL17: AWS | GM17: AWS | GN17: SQL | GO17: CES | GP17: SQL | GQ17: SQL | GR17: SQL | GS17: CES | GT17: SQL | GU17: SQL | GV17: SQL | GW17: CES | GX17: SQL | GY17: SQL | GZ17: SQL | HA17: CES | HB17: SQL | HC17: SQL | HD17: ML | HE17: CES | HF17: ML | HG17: ML | HH17: ML | HI17: ML | HJ17: ML | HK17: ML | HL17: ML | HM17: ML | HN17: ML | HO17: ML
A18: 11 | B18: 360498 | C18: dhanapriyagiddaluru@gmail.com | D18: Giddaluru Dhanapriya | E18: =IF(COUNTIF($AH18:$UG18,E$7)=0,"",COUNTIF($AH18:$UG18,E$7)) | F18: =IF(COUNTIF($AH18:$UG18,F$7)=0,"",COUNTIF($AH18:$UG18,F$7)) | G18: =IF(COUNTIF($AH18:$UG18,G$7)=0,"",COUNTIF($AH18:$UG18,G$7)) -> 11 | H18: =IF(COUNTIF($AH18:$UG18,H$7)=0,"",COUNTIF($AH18:$UG18,H$7)) | I18: =IF(COUNTIF($AH18:$UG18,I$7)=0,"",COUNTIF($AH18:$UG18,I$7)) | J18: =IF(COUNTIF($AH18:$UG18,J$7)=0,"",COUNTIF($AH18:$UG18,J$7)) | K18: =IF(COUNTIF($AH18:$UG18,K$7)=0,"",COUNTIF($AH18:$UG18,K$7)) -> 28 | L18: =IF(COUNTIF($AH18:$UG18,L$7)=0,"",COUNTIF($AH18:$UG18,L$7)) | ... Z18: =IF(COUNTIF($AH18:$UG18,Z$7)=0,"",COUNTIF($AH18:$UG18,Z$7)) | AA18: =BV18 -> Yes | AB18: =EY18 -> 0 | AC18: =IF(SUM(E18:Z18)=0,"",SUM(E18:Z18)) -> 168 | AD18: =IF(SUM(E18:Z18)>=1,AC18-SUM(V18:X18),"") -> 163 | AE18: =IF(COUNTA(AH18:UI18)=0,"",IF(COUNTA(AH18:UI18)=0,0,AG66)) -> 46 | AF18: =IF(AE18="","",AE18/((COUNTA(AH18:BU18)+COUNTA(BW18:EX18)+COUNTA(EZ18:#REF!))/4)) -> 1.5206612 | AG18: =IF(AD18="","",AD18/AC18) -> 0.9702381 | AH18: PY | AI18: PY | AJ18: PY | AK18: PY | AL18: PY | AM18: PY | AN18: PY | AO18: PY | AP18: PY | AQ18: GO | AR18: PY | AS18: PY | AT18: PY | AU18: PY | AV18: PY | AW18: PY | AX18: PY | AY18: CES | AZ18: PY | BA18: PY | BB18: PY | BC18: PY | BD18: PY | BE18: PY | BF18: Ab | BG18: Ab | BH18: Ab | BI18: Ab | BJ18: PY | BK18: PY | BL18: PY | BM18: PY | BN18: PY | BO18: CES | BP18: PY | BQ18: PY | BR18: PY | BS18: PY | BT18: PY | BU18: PY | BV18: Yes | BW18: PY | BX18: CES | BY18: PY | BZ18: PY | CA18: PY | CB18: PY | CC18: PY | CD18: PY | CE18: PY | CF18: PY | CG18: PY | CH18: PY | CI18: PY | CJ18: PY | CK18: PY | CL18: PY | CM18: PY | CN18: CES | CO18: PY | CP18: PY | CQ18: NY | CR18: NY | CS18: NY | CT18: NY | CU18: NY | CV18: CES | CW18: NY | CX18: NY | CY18: PS | CZ18: PS | DA18: PS | DB18: PS | DC18: PS | DD18: CES | DE18: PS | DF18: PS | DG18: PS | DH18: CES | DI18: PS | DJ18: PS | DK18: PS | DL18: CES | DM18: PS | DN18: PS | DO18: PS | DP18: PS | DQ18: PS | DR18: PS | DS18: PS | DT18: CES | DU18: PS | DV18: PS | DW18: MTP | DX18: MTP | DY18: MTP | DZ18: MTP | EA18: MTP | EB18: CES | EC18: MTP | ED18: MTP | EE18: SB | EF18: CES | EG18: SB | EH18: SB | EI18: SB | EJ18: CES | EK18: SB | EL18: SB | EM18: SB | EN18: CES | EO18: SB | EP18: SB | EQ18: DS | ER18: CES | ES18: DS | ET18: DS | EU18: Ab | EV18: CES | EW18: DS | EX18: DS | EZ18: DS | FA18: CES | FB18: DS | FC18: DS | FD18: DS | FE18: CES | FF18: DS | FG18: DS | FH18: IS | FI18: CES | FJ18: IS | FK18: IS | FL18: IS | FM18: CES | FN18: IS | FO18: IS | FP18: AWS | FQ18: AWS | FR18: AWS | FS18: AWS | FT18: AWS | FU18: CES | FV18: AWS | FW18: AWS | FX18: AWS | FY18: CES | FZ18: AWS | GA18: AWS | GB18: AWS | GC18: AWS | GD18: AWS | GE18: AWS | GF18: AWS | GG18: CES | GH18: AWS | GI18: AWS | GJ18: AWS | GK18: CES | GL18: AWS | GM18: AWS | GN18: SQL | GO18: CES | GP18: SQL | GQ18: SQL | GR18: SQL | GS18: CES | GT18: SQL | GU18: SQL | GV18: SQL | GW18: CES | GX18: SQL | GY18: SQL | GZ18: SQL | HA18: CES | HB18: SQL | HC18: SQL | HD18: ML | HE18: CES | HF18: ML | HG18: ML | HH18: ML | HI18: ML | HJ18: ML | HK18: ML | HL18: ML | HM18: ML | HN18: ML | HO18: ML
A19: 12 | B19: 360520 | C19: rajasekar18rajasekar@gmail.com | D19: Rajasekar Dhanasekar | E19: =IF(COUNTIF($AH19:$UG19,E$7)=0,"",COUNTIF($AH19:$UG19,E$7)) | F19: =IF(COUNTIF($AH19:$UG19,F$7)=0,"",COUNTIF($AH19:$UG19,F$7)) | G19: =IF(COUNTIF($AH19:$UG19,G$7)=0,"",COUNTIF($AH19:$UG19,G$7)) -> 11 | H19: =IF(COUNTIF($AH19:$UG19,H$7)=0,"",COUNTIF($AH19:$UG19,H$7)) | I19: =IF(COUNTIF($AH19:$UG19,I$7)=0,"",COUNTIF($AH19:$UG19,I$7)) | J19: =IF(COUNTIF($AH19:$UG19,J$7)=0,"",COUNTIF($AH19:$UG19,J$7)) | K19: =IF(COUNTIF($AH19:$UG19,K$7)=0,"",COUNTIF($AH19:$UG19,K$7)) -> 28 | L19: =IF(COUNTIF($AH19:$UG19,L$7)=0,"",COUNTIF($AH19:$UG19,L$7)) | ... Z19: =IF(COUNTIF($AH19:$UG19,Z$7)=0,"",COUNTIF($AH19:$UG19,Z$7)) | AA19: =BV19 -> Yes | AB19: =EY19 -> 0 | AC19: =IF(SUM(E19:Z19)=0,"",SUM(E19:Z19)) -> 171 | AD19: =IF(SUM(E19:Z19)>=1,AC19-SUM(V19:X19),"") -> 163 | AE19: =IF(COUNTA(AH19:UI19)=0,"",IF(COUNTA(AH19:UI19)=0,0,AG67)) -> 45 | AF19: =IF(AE19="","",AE19/((COUNTA(AH19:BU19)+COUNTA(BW19:EX19)+COUNTA(EZ19:#REF!))/4)) -> 1.4876033 | AG19: =IF(AD19="","",AD19/AC19) -> 0.95321637 | AH19: PY | AI19: PY | AJ19: PY | AK19: PY | AL19: PY | AM19: PY | AN19: PY | AO19: PY | AP19: PY | AQ19: GO | AR19: PY | AS19: PY | AT19: PY | AU19: PY | AV19: PY | AW19: PY | AX19: PY | AY19: CES | AZ19: PY | BA19: PY | BB19: PY | BC19: PY | BD19: PY | BE19: PY | BF19: PY | BG19: CES | BH19: PY | BI19: PY | BJ19: PY | BK19: PY | BL19: PY | BM19: PY | BN19: PY | BO19: CES | BP19: PY | BQ19: PY | BR19: PY | BS19: PY | BT19: PY | BU19: PY | BV19: Yes | BW19: PY | BX19: CES | BY19: PY | BZ19: PY | CA19: PY | CB19: PY | CC19: PY | CD19: PY | CE19: PY | CF19: PY | CG19: PY | CH19: PY | CI19: Ab | CJ19: Ab | CK19: Ab | CL19: Ab | CM19: PY | CN19: CES | CO19: PY | CP19: PY | CQ19: NY | CR19: NY | CS19: NY | CT19: NY | CU19: NY | CV19: CES | CW19: NY | CX19: NY | CY19: PS | CZ19: PS | DA19: PS | DB19: PS | DC19: PS | DD19: CES | DE19: PS | DF19: PS | DG19: PS | DH19: CES | DI19: PS | DJ19: PS | DK19: PS | DL19: CES | DM19: PS | DN19: PS | DO19: PS | DP19: PS | DQ19: PS | DR19: PS | DS19: PS | DT19: CES | DU19: PS | DV19: PS | DW19: MTP | DX19: MTP | DY19: MTP | DZ19: MTP | EA19: MTP | EB19: CES | EC19: MTP | ED19: MTP | EE19: SB | EF19: CES | EG19: SB | EH19: SB | EI19: SB | EJ19: CES | EK19: SB | EL19: SB | EM19: SB | EN19: CES | EO19: SB | EP19: SB | EQ19: DS | ER19: CES | ES19: DS | ET19: DS | EU19: DS | EV19: CES | EW19: DS | EX19: DS | EZ19: DS | FA19: CES | FB19: DS | FC19: DS | FD19: DS | FE19: CES | FF19: DS | FG19: DS | FH19: IS | FI19: CES | FJ19: IS | FK19: IS | FL19: IS | FM19: CES | FN19: IS | FO19: IS | FP19: AWS | FQ19: AWS | FR19: AWS | FS19: AWS | FT19: Ab | FU19: Ab | FV19: Ab | FW19: Ab | FX19: AWS | FY19: CES | FZ19: AWS | GA19: AWS | GB19: AWS | GC19: AWS | GD19: AWS | GE19: AWS | GF19: AWS | GG19: CES | GH19: AWS | GI19: AWS | GJ19: AWS | GK19: CES | GL19: AWS | GM19: AWS | GN19: SQL | GO19: CES | GP19: SQL | GQ19: SQL | GR19: SQL | GS19: CES | GT19: SQL | GU19: SQL | GV19: SQL | GW19: CES | GX19: SQL | GY19: SQL | GZ19: SQL | HA19: CES | HB19: SQL | HC19: SQL | HD19: ML | HE19: CES | HF19: ML | HG19: ML | HH19: ML | HI19: ML | HJ19: ML | HK19: ML | HL19: ML | HM19: ML | HN19: ML | HO19: ML
A20: 13 | B20: 361316 | C20: saran.t.1423@gmail.com | D20: Saran Thennarasu | E20: =IF(COUNTIF($AH20:$UG20,E$7)=0,"",COUNTIF($AH20:$UG20,E$7)) | F20: =IF(COUNTIF($AH20:$UG20,F$7)=0,"",COUNTIF($AH20:$UG20,F$7)) | G20: =IF(COUNTIF($AH20:$UG20,G$7)=0,"",COUNTIF($AH20:$UG20,G$7)) -> 11 | H20: =IF(COUNTIF($AH20:$UG20,H$7)=0,"",COUNTIF($AH20:$UG20,H$7)) | I20: =IF(COUNTIF($AH20:$UG20,I$7)=0,"",COUNTIF($AH20:$UG20,I$7)) | J20: =IF(COUNTIF($AH20:$UG20,J$7)=0,"",COUNTIF($AH20:$UG20,J$7)) | K20: =IF(COUNTIF($AH20:$UG20,K$7)=0,"",COUNTIF($AH20:$UG20,K$7)) -> 29 | L20: =IF(COUNTIF($AH20:$UG20,L$7)=0,"",COUNTIF($AH20:$UG20,L$7)) | ... Z20: =IF(COUNTIF($AH20:$UG20,Z$7)=0,"",COUNTIF($AH20:$UG20,Z$7)) | AA20: =BV20 -> Yes | AB20: =EY20 -> 0 | AC20: =IF(SUM(E20:Z20)=0,"",SUM(E20:Z20)) -> 172 | AD20: =IF(SUM(E20:Z20)>=1,AC20-SUM(V20:X20),"") -> 168 | AE20: =IF(COUNTA(AH20:UI20)=0,"",IF(COUNTA(AH20:UI20)=0,0,AG69)) -> 46 | AF20: =IF(AE20="","",AE20/((COUNTA(AH20:BU20)+COUNTA(BW20:EX20)+COUNTA(EZ20:#REF!))/4)) -> 1.5206612 | AG20: =IF(AD20="","",AD20/AC20) -> 0.97674419 | AH20: PY | AI20: PY | AJ20: PY | AK20: PY | AL20: PY | AM20: PY | AN20: PY | AO20: PY | AP20: PY | AQ20: GO | AR20: PY | AS20: PY | AT20: PY | AU20: PY | AV20: PY | AW20: PY | AX20: PY | AY20: CES | AZ20: PY | BA20: PY | BB20: PY | BC20: PY | BD20: PY | BE20: PY | BF20: PY | BG20: CES | BH20: PY | BI20: PY | BJ20: PY | BK20: PY | BL20: PY | BM20: PY | BN20: PY | BO20: CES | BP20: PY | BQ20: PY | BR20: PY | BS20: PY | BT20: PY | BU20: PY | BV20: Yes | BW20: PY | BX20: CES | BY20: PY | BZ20: PY | CA20: PY | CB20: PY | CC20: PY | CD20: PY | CE20: PY | CF20: PY | CG20: PY | CH20: PY | CI20: PY | CJ20: PY | CK20: PY | CL20: PY | CM20: PY | CN20: CES | CO20: PY | CP20: PY | CQ20: NY | CR20: NY | CS20: NY | CT20: NY | CU20: NY | CV20: CES | CW20: NY | CX20: NY | CY20: PS | CZ20: PS | DA20: PS | DB20: PS | DC20: PS | DD20: CES | DE20: PS | DF20: PS | DG20: PS | DH20: CES | DI20: PS | DJ20: PS | DK20: PS | DL20: CES | DM20: PS | DN20: PS | DO20: PS | DP20: PS | DQ20: PS | DR20: PS | DS20: PS | DT20: CES | DU20: PS | DV20: PS | DW20: MTP | DX20: MTP | DY20: MTP | DZ20: MTP | EA20: MTP | EB20: CES | EC20: MTP | ED20: MTP | EE20: SB | EF20: CES | EG20: SB | EH20: SB | EI20: SB | EJ20: CES | EK20: SB | EL20: SB | EM20: SB | EN20: CES | EO20: SB | EP20: SB | EQ20: DS | ER20: CES | ES20: DS | ET20: DS | EU20: DS | EV20: CES | EW20: DS | EX20: DS | EZ20: DS | FA20: CES | FB20: DS | FC20: DS | FD20: DS | FE20: CES | FF20: DS | FG20: DS | FH20: IS | FI20: CES | FJ20: IS | FK20: IS | FL20: IS | FM20: CES | FN20: IS | FO20: IS | FP20: Ab | FQ20: Ab | FR20: Ab | FS20: Ab | FT20: AWS | FU20: CES | FV20: AWS | FW20: AWS | FX20: AWS | FY20: CES | FZ20: AWS | GA20: AWS | GB20: AWS | GC20: AWS | GD20: AWS | GE20: AWS | GF20: AWS | GG20: CES | GH20: AWS | GI20: AWS | GJ20: AWS | GK20: CES | GL20: AWS | GM20: AWS | GN20: SQL | GO20: CES | GP20: SQL | GQ20: SQL | GR20: SQL | GS20: CES | GT20: SQL | GU20: SQL | GV20: SQL | GW20: CES | GX20: SQL | GY20: SQL | GZ20: SQL | HA20: CES | HB20: SQL | HC20: SQL | HD20: ML | HE20: CES | HF20: ML | HG20: ML | HH20: ML | HI20: ML | HJ20: ML | HK20: ML | HL20: ML | HM20: ML | HN20: ML | HO20: ML
A21: 14 | B21: 361399 | C21: arung26603@gmail.com | D21: Arunkumar G | E21: =IF(COUNTIF($AH21:$UG21,E$7)=0,"",COUNTIF($AH21:$UG21,E$7)) | F21: =IF(COUNTIF($AH21:$UG21,F$7)=0,"",COUNTIF($AH21:$UG21,F$7)) | G21: =IF(COUNTIF($AH21:$UG21,G$7)=0,"",COUNTIF($AH21:$UG21,G$7)) -> 7 | H21: =IF(COUNTIF($AH21:$UG21,H$7)=0,"",COUNTIF($AH21:$UG21,H$7)) | I21: =IF(COUNTIF($AH21:$UG21,I$7)=0,"",COUNTIF($AH21:$UG21,I$7)) | J21: =IF(COUNTIF($AH21:$UG21,J$7)=0,"",COUNTIF($AH21:$UG21,J$7)) | K21: =IF(COUNTIF($AH21:$UG21,K$7)=0,"",COUNTIF($AH21:$UG21,K$7)) -> 26 | L21: =IF(COUNTIF($AH21:$UG21,L$7)=0,"",COUNTIF($AH21:$UG21,L$7)) | ... Z21: =IF(COUNTIF($AH21:$UG21,Z$7)=0,"",COUNTIF($AH21:$UG21,Z$7)) | AA21: =BV21 -> Yes | AB21: =EY21 -> 0 | AC21: =IF(SUM(E21:Z21)=0,"",SUM(E21:Z21)) -> 172 | AD21: =IF(SUM(E21:Z21)>=1,AC21-SUM(V21:X21),"") -> 148 | AE21: =IF(COUNTA(AH21:UI21)=0,"",IF(COUNTA(AH21:UI21)=0,0,AG70)) -> 41 | AF21: =IF(AE21="","",AE21/((COUNTA(AH21:BU21)+COUNTA(BW21:EX21)+COUNTA(EZ21:#REF!))/4)) -> 1.3553719 | AG21: =IF(AD21="","",AD21/AC21) -> 0.86046512 | AH21: PY | AI21: PY | AJ21: PY | AK21: PY | AL21: PY | AM21: PY | AN21: PY | AO21: PY | AP21: PY | AQ21: GO | AR21: PY | AS21: PY | AT21: PY | AU21: PY | AV21: PY | AW21: PY | AX21: PY | AY21: CES | AZ21: PY | BA21: PY | BB21: PY | BC21: PY | BD21: PY | BE21: PY | BF21: Ab | BG21: Ab | BH21: Ab | BI21: Ab | BJ21: PY | BK21: PY | BL21: PY | BM21: PY | BN21: PY | BO21: CES | BP21: PY | BQ21: PY | BR21: PY | BS21: PY | BT21: PY | BU21: PY | BV21: Yes | BW21: PY | BX21: CES | BY21: PY | BZ21: PY | CA21: PY | CB21: PY | CC21: PY | CD21: PY | CE21: PY | CF21: PY | CG21: PY | CH21: PY | CI21: Ab | CJ21: Ab | CK21: Ab | CL21: Ab | CM21: PY | CN21: CES | CO21: PY | CP21: PY | CQ21: NY | CR21: NY | CS21: NY | CT21: NY | CU21: NY | CV21: CES | CW21: NY | CX21: NY | CY21: PS | CZ21: PS | DA21: PS | DB21: PS | DC21: PS | DD21: CES | DE21: PS | DF21: PS | DG21: PS | DH21: CES | DI21: PS | DJ21: PS | DK21: PS | DL21: CES | DM21: PS | DN21: PS | DO21: PS | DP21: PS | DQ21: PS | DR21: PS | DS21: PS | DT21: CES | DU21: PS | DV21: PS | DW21: MTP | DX21: MTP | DY21: MTP | DZ21: MTP | EA21: Ab | EB21: Ab | EC21: Ab | ED21: Ab | EE21: SB | EF21: CES | EG21: SB | EH21: SB | EI21: SB | EJ21: CES | EK21: SB | EL21: SB | EM21: SB | EN21: CES | EO21: SB | EP21: SB | EQ21: Ab | ER21: Ab | ES21: Ab | ET21: Ab | EU21: DS | EV21: CES | EW21: DS | EX21: DS | EZ21: DS | FA21: CES | FB21: DS | FC21: DS | FD21: DS | FE21: CES | FF21: DS | FG21: DS | FH21: IS | FI21: CES | FJ21: IS | FK21: IS | FL21: IS | FM21: CES | FN21: IS | FO21: IS | FP21: Ab | FQ21: Ab | FR21: Ab | FS21: Ab | FT21: AWS | FU21: CES | FV21: AWS | FW21: AWS | FX21: AWS | FY21: CES | FZ21: AWS | GA21: AWS | GB21: AWS | GC21: AWS | GD21: AWS | GE21: AWS | GF21: AWS | GG21: CES | GH21: AWS | GI21: AWS | GJ21: AWS | GK21: CES | GL21: AWS | GM21: AWS | GN21: SQL | GO21: CES | GP21: SQL | GQ21: SQL | GR21: SQL | GS21: CES | GT21: SQL | GU21: SQL | GV21: SQL | GW21: CES | GX21: SQL | GY21: SQL | GZ21: SQL | HA21: CES | HB21: SQL | HC21: SQL | HD21: ML | HE21: CES | HF21: ML | HG21: ML | HH21: Ab | HI21: Ab | HJ21: Ab | HK21: Ab | HL21: ML | HM21: ML | HN21: ML | HO21: ML
A22: 15 | B22: 361652 | C22: tharunkumarvthangadurai@gmail.com | D22: Tharunkumar T | E22: =IF(COUNTIF($AH22:$UG22,E$7)=0,"",COUNTIF($AH22:$UG22,E$7)) | F22: =IF(COUNTIF($AH22:$UG22,F$7)=0,"",COUNTIF($AH22:$UG22,F$7)) | G22: =IF(COUNTIF($AH22:$UG22,G$7)=0,"",COUNTIF($AH22:$UG22,G$7)) -> 4 | H22: =IF(COUNTIF($AH22:$UG22,H$7)=0,"",COUNTIF($AH22:$UG22,H$7)) | I22: =IF(COUNTIF($AH22:$UG22,I$7)=0,"",COUNTIF($AH22:$UG22,I$7)) | J22: =IF(COUNTIF($AH22:$UG22,J$7)=0,"",COUNTIF($AH22:$UG22,J$7)) | K22: =IF(COUNTIF($AH22:$UG22,K$7)=0,"",COUNTIF($AH22:$UG22,K$7)) -> 13 | L22: =IF(COUNTIF($AH22:$UG22,L$7)=0,"",COUNTIF($AH22:$UG22,L$7)) | ... Z22: =IF(COUNTIF($AH22:$UG22,Z$7)=0,"",COUNTIF($AH22:$UG22,Z$7)) | AA22: =BV22 -> Yes | AB22: =EY22 -> 0 | AC22: =IF(SUM(E22:Z22)=0,"",SUM(E22:Z22)) -> 175 | AD22: =IF(SUM(E22:Z22)>=1,AC22-SUM(V22:X22),"") -> 75 | AE22: =IF(COUNTA(AH22:UI22)=0,"",IF(COUNTA(AH22:UI22)=0,0,AG71)) -> 22 | AF22: =IF(AE22="","",AE22/((COUNTA(AH22:BU22)+COUNTA(BW22:EX22)+COUNTA(EZ22:#REF!))/4)) -> 0.72727273 | AG22: =IF(AD22="","",AD22/AC22) -> 0.42857143 | AH22: PY | AI22: PY | AJ22: PY | AK22: PY | AL22: PY | AM22: PY | AN22: PY | AO22: PY | AP22: Ab | AQ22: Ab | AR22: Ab | AS22: Ab | AT22: Ab | AU22: Ab | AV22: Ab | AW22: Ab | AX22: PY | AY22: CES | AZ22: PY | BA22: PY | BB22: PY | BC22: PY | BD22: PY | BE22: PY | BF22: Ab | BG22: Ab | BH22: Ab | BI22: Ab | BJ22: Ab | BK22: Ab | BL22: Ab | BM22: Ab | BN22: Ab | BO22: Ab | BP22: Ab | BQ22: Ab | BR22: Ab | BS22: Ab | BT22: Ab | BU22: Ab | BV22: Yes | BW22: PY | BX22: CES | BY22: PY | BZ22: PY | CA22: PY | CB22: PY | CC22: PY | CD22: PY | CE22: PY | CF22: PY | CG22: PY | CH22: PY | CI22: Ab | CJ22: Ab | CK22: Ab | CL22: Ab | CM22: Ab | CN22: Ab | CO22: Ab | CP22: Ab | CQ22: NY | CR22: NY | CS22: NY | CT22: NY | CU22: NY | CV22: CES | CW22: NY | CX22: NY | CY22: PS | CZ22: PS | DA22: PS | DB22: PS | DC22: PS | DD22: CES | DE22: PS | DF22: PS | DG22: Ab | DH22: Ab | DI22: Ab | DJ22: Ab | DK22: PS | DL22: CES | DM22: PS | DN22: PS | DO22: Ab | DP22: Ab | DQ22: Ab | DR22: Ab | DS22: PS | DT22: CES | DU22: PS | DV22: PS | DW22: Ab | DX22: Ab | DY22: Ab | DZ22: Ab | EA22: Ab | EB22: Ab | EC22: Ab | ED22: Ab | EE22: SB | EF22: CES | EG22: SB | EH22: SB | EI22: SB | EJ22: CES | EK22: SB | EL22: SB | EM22: SB | EN22: CES | EO22: SB | EP22: SB | EQ22: DS | ER22: CES | ES22: DS | ET22: DS | EU22: Ab | EV22: Ab | EW22: Ab | EX22: Ab | EZ22: Ab | FA22: Ab | FB22: Ab | FC22: Ab | FD22: Ab | FE22: Ab | FF22: Ab | FG22: Ab | FH22: Ab | FI22: Ab | FJ22: Ab | FK22: Ab | FL22: Ab | FM22: Ab | FN22: Ab | FO22: Ab | FP22: Ab | FQ22: Ab | FR22: Ab | FS22: Ab | FT22: AWS | FU22: CES | FV22: AWS | FW22: AWS | FX22: AWS | FY22: CES | FZ22: AWS | GA22: AWS | GB22: AWS | GC22: AWS | GD22: AWS | GE22: AWS | GF22: AWS | GG22: CES | GH22: AWS | GI22: AWS | GJ22: Ab | GK22: Ab | GL22: Ab | GM22: Ab | GN22: Ab | GO22: Ab | GP22: Ab | GQ22: Ab | GR22: Ab | GS22: Ab | GT22: Ab | GU22: Ab | GV22: Ab | GW22: Ab | GX22: Ab | GY22: Ab | GZ22: Ab | HA22: Ab | HB22: Ab | HC22: Ab | HD22: Ab | HE22: Ab | HF22: Ab | HG22: Ab | HH22: Ab | HI22: Ab | HJ22: Ab | HK22: Ab | HL22: ML | HM22: ML | HN22: ML | HO22: ML
